<?xml version="1.0" ?>
<!-- =================================================================================== -->
<!-- |    This document was autogenerated by xacro from /home/michael/catkin_ws/src/Butler_3.0/butler_description/urdf/butler_complete.urdf.xacro | -->
<!-- |    EDITING THIS FILE BY HAND IS NOT RECOMMENDED                                 | -->
<!-- =================================================================================== -->
<robot name="butler_3">
    <!-- This file is only for backward compatibility before the "mir_100" to "mir" rename. -->
    <!-- necessary because args cannot be accessed inside ${} expressions -->
    <link name="mir_base_footprint" />
    <joint name="mir_base_joint" type="fixed">
        <parent link="mir_base_footprint" />
        <child link="mir_base_link" />
        <origin rpy="0 0 0" xyz="0 0 0" />
    </joint>
    <link name="mir_base_link">
        <inertial>
            <mass value="77.0" />
            <origin rpy="0 0 0" xyz="-0.012354000000000004 0.0 0.15" />
            <inertia ixx="0.8341663330000001" ixy="0.0" ixz="0.0" iyy="1.8608325890000004" iyz="0.0" izz="2.1816657939999997" />
        </inertial>
        <visual>
            <origin rpy="0 0 0" xyz="0.037646 0 0" />
            <geometry>
                <mesh filename="package://mir_description/meshes/visual/mir_100_base.stl" />
            </geometry>
            <material name="white">
                <color rgba="1 1 1 1" />
            </material>
        </visual>
        <collision>
            <origin rpy="0 0 0" xyz="0.037646 0 0" />
            <geometry>
                <mesh filename="package://mir_description/meshes/collision/mir_100_base.stl" />
            </geometry>
        </collision>
    </link>
    <gazebo reference="mir_base_link">
        <material>Gazebo/White</material>
        <plugin name="gazebo_ros_control" filename="libgazebo_ros_control.so">
            <robotNamespace>/</robotNamespace>
        </plugin>
    </gazebo>
    <!-- IMU -->
    <joint name="mir_base_link_to_imu_joint" type="fixed">
        <parent link="mir_base_link" />
        <child link="mir_imu_link" />
        <origin rpy="0 0 0" xyz="0.0 0.0 0.25" />
        <!-- same as real MiR -->
    </joint>
    <link name="mir_imu_link" />
    <gazebo>
        <plugin filename="libhector_gazebo_ros_imu.so" name="imu_plugin">
            <updateRate>50.0</updateRate>
            <bodyName>mir_imu_link</bodyName>
            <frameId>imu_frame</frameId>
            <!-- from real MiR -->
            <topicName>imu_data</topicName>
            <accelDrift>0.0 0.0 0.0</accelDrift>
            <accelGaussianNoise>0.007071067811865475 0.01 0.011401754250991379</accelGaussianNoise>
            <!-- real MiR linear_acceleration_covariance: [5e-05, 0.0, 0.0, 0.0, 0.0001, 0.0, 0.0, 0.0, 0.00013] -->
            <rateDrift>0.0 0.0 0.0</rateDrift>
            <rateGaussianNoise>0.00282842712474619 0.00282842712474619 0.0005477225575051661</rateGaussianNoise>
            <!-- real MiR angular_velocity_covariance: [8e-06, 0.0, 0.0, 0.0, 8e-06, 0.0, 0.0, 0.0, 3e-07] -->
            <yawDrift>0.0</yawDrift>
            <yawGaussianNoise>0.31622776601683794</yawGaussianNoise>
            <!-- real MiR orientation_covariance: [0.1, 0.0, 0.0, 0.0, 0.1, 0.0, 0.0, 0.0, 0.1] -->
        </plugin>
    </gazebo>
    <!-- Create an alias for imu_link. This is necessary because the real MiR's
         TF has imu_link, but the imu_data topic is published in the imu_frame
         frame. -->
    <joint name="mir_imu_link_to_imu_frame_joint" type="fixed">
        <parent link="mir_imu_link" />
        <child link="mir_imu_frame" />
        <origin rpy="0 0 0" xyz="0 0 0" />
    </joint>
    <link name="mir_imu_frame" />
    <!-- Laser scanners -->
    <joint name="mir_base_link_to_front_laser_joint" type="fixed">
        <parent link="mir_base_link" />
        <child link="mir_front_laser_link" />
        <origin rpy="0.0 0.0 0.7853981633974483" xyz="0.42964600000000003 0.2358 0.1914" />
    </joint>
    <link name="mir_front_laser_link">
        <visual>
            <origin rpy="3.141592653589793 0 0" xyz="0.0 0.0 0.0" />
            <geometry>
                <mesh filename="package://mir_description/meshes/visual/sick_lms-100.stl" />
            </geometry>
            <!-- <xacro:insert_block name="material_yellow" /> -->
            <material name="black">
                <color rgba="0.1 0.1 0.1 1" />
            </material>
        </visual>
        <collision>
            <origin rpy="3.141592653589793 0 0" xyz="0.0 0.0 0.0" />
            <geometry>
                <mesh filename="package://mir_description/meshes/visual/sick_lms-100.stl" />
            </geometry>
        </collision>
        <inertial>
            <mass value="1.2" />
            <origin xyz="0 0 0" rpy="0 0 0" />
            <inertia ixx="0.005824997669999999" ixy="0.0" ixz="0.0" iyy="0.00585609765756" iyz="0.0" izz="0.00483609806556" />
        </inertial>
    </link>
    <gazebo reference="mir_front_laser_link">
        <!-- <material value="Gazebo/Yellow" /> -->
        <material value="Gazebo/FlatBlack" />
        <sensor name="mir_front_laser_link" type="ray">
            <pose>0 0 0 0 0 0</pose>
            <visualize>false</visualize>
            <update_rate>12.5</update_rate>
            <ray>
                <scan>
                    <horizontal>
                        <samples>541</samples>
                        <resolution>1</resolution>
                        <!-- has to be 1; actual resolution will be computed from number of samples + min_angle/max_angle -->
                        <min_angle>-2.35619449615</min_angle>
                        <max_angle>2.35619449615</max_angle>
                    </horizontal>
                </scan>
                <range>
                    <min>0.05</min>
                    <max>29.0</max>
                    <resolution>0.01</resolution>
                </range>
                <noise>
                    <type>gaussian</type>
                    <!-- Noise parameters based on published spec for S300 achieving
                 "+-29mm" accuracy at range < 3m (~0.01 of the range) at
                 1 sigma. -->
                    <mean>0.0</mean>
                    <stddev>0.01</stddev>
                </noise>
            </ray>
            <plugin filename="libgazebo_ros_laser.so" name="gazebo_ros_front_laser_link_controller">
                <frameName>mir_front_laser_link</frameName>
                <topicName>f_scan</topicName>
            </plugin>
        </sensor>
    </gazebo>
    <joint name="mir_base_link_to_back_laser_joint" type="fixed">
        <parent link="mir_base_link" />
        <child link="mir_back_laser_link" />
        <origin rpy="0.0 0.0 -2.356194490192345" xyz="-0.354354 -0.2358 0.1914" />
    </joint>
    <link name="mir_back_laser_link">
        <visual>
            <origin rpy="3.141592653589793 0 0" xyz="0.0 0.0 0.0" />
            <geometry>
                <mesh filename="package://mir_description/meshes/visual/sick_lms-100.stl" />
            </geometry>
            <!-- <xacro:insert_block name="material_yellow" /> -->
            <material name="black">
                <color rgba="0.1 0.1 0.1 1" />
            </material>
        </visual>
        <collision>
            <origin rpy="3.141592653589793 0 0" xyz="0.0 0.0 0.0" />
            <geometry>
                <mesh filename="package://mir_description/meshes/visual/sick_lms-100.stl" />
            </geometry>
        </collision>
        <inertial>
            <mass value="1.2" />
            <origin xyz="0 0 0" rpy="0 0 0" />
            <inertia ixx="0.005824997669999999" ixy="0.0" ixz="0.0" iyy="0.00585609765756" iyz="0.0" izz="0.00483609806556" />
        </inertial>
    </link>
    <gazebo reference="mir_back_laser_link">
        <!-- <material value="Gazebo/Yellow" /> -->
        <material value="Gazebo/FlatBlack" />
        <sensor name="mir_back_laser_link" type="ray">
            <pose>0 0 0 0 0 0</pose>
            <visualize>false</visualize>
            <update_rate>12.5</update_rate>
            <ray>
                <scan>
                    <horizontal>
                        <samples>541</samples>
                        <resolution>1</resolution>
                        <!-- has to be 1; actual resolution will be computed from number of samples + min_angle/max_angle -->
                        <min_angle>-2.35619449615</min_angle>
                        <max_angle>2.35619449615</max_angle>
                    </horizontal>
                </scan>
                <range>
                    <min>0.05</min>
                    <max>29.0</max>
                    <resolution>0.01</resolution>
                </range>
                <noise>
                    <type>gaussian</type>
                    <!-- Noise parameters based on published spec for S300 achieving
                 "+-29mm" accuracy at range < 3m (~0.01 of the range) at
                 1 sigma. -->
                    <mean>0.0</mean>
                    <stddev>0.01</stddev>
                </noise>
            </ray>
            <plugin filename="libgazebo_ros_laser.so" name="gazebo_ros_back_laser_link_controller">
                <frameName>mir_back_laser_link</frameName>
                <topicName>b_scan</topicName>
            </plugin>
        </sensor>
    </gazebo>
    <!-- Ultrasound sensors -->
    <joint name="mir_us_1_joint" type="fixed">
        <!-- right ultrasound -->
        <parent link="mir_base_link" />
        <child link="mir_us_1_frame" />
        <origin rpy="0 0 0" xyz="0.45 -0.12 0.16 " />
        <!-- from visually matching to the mesh of the MiR -->
    </joint>
    <link name="mir_us_1_frame" />
    <joint name="mir_us_2_joint" type="fixed">
        <!-- left ultrasound -->
        <parent link="mir_base_link" />
        <child link="mir_us_2_frame" />
        <origin rpy="0 0 0" xyz="0.45 0.12 0.16 " />
        <!-- from visually matching to the mesh of the MiR -->
    </joint>
    <link name="mir_us_2_frame" />
    <joint name="mir_left_wheel_joint" type="continuous">
        <origin rpy="0 0 0" xyz="0.0 0.222604 0.0625" />
        <parent link="mir_base_link" />
        <child link="mir_left_wheel_link" />
        <axis xyz="0 1 0" />
        <limit effort="100" velocity="20.0" />
    </joint>
    <link name="mir_left_wheel_link">
        <inertial>
            <mass value="1.0" />
            <origin rpy="1.5707963267948966 0 0" xyz="0 0 0" />
            <inertia ixx="0.001061895408575" ixy="0.0" ixz="0.0" iyy="0.001061895408575" iyz="0.0" izz="0.001953125" />
        </inertial>
        <visual>
            <origin rpy="1.5707963267948966 0 0" xyz="0 0 0" />
            <geometry>
                <cylinder length="0.032" radius="0.0625" />
            </geometry>
            <material name="black">
                <color rgba="0.1 0.1 0.1 1" />
            </material>
        </visual>
        <collision>
            <origin rpy="1.5707963267948966 0 0" xyz="0 0 0" />
            <geometry>
                <cylinder length="0.032" radius="0.0625" />
            </geometry>
        </collision>
    </link>
    <gazebo reference="mir_left_wheel_link">
        <material>Gazebo/FlatBlack</material>
    </gazebo>
    <joint name="mir_right_wheel_joint" type="continuous">
        <origin rpy="0 0 0" xyz="0.0 -0.222604 0.0625" />
        <parent link="mir_base_link" />
        <child link="mir_right_wheel_link" />
        <axis xyz="0 1 0" />
        <limit effort="100" velocity="20.0" />
    </joint>
    <link name="mir_right_wheel_link">
        <inertial>
            <mass value="1.0" />
            <origin rpy="1.5707963267948966 0 0" xyz="0 0 0" />
            <inertia ixx="0.001061895408575" ixy="0.0" ixz="0.0" iyy="0.001061895408575" iyz="0.0" izz="0.001953125" />
        </inertial>
        <visual>
            <origin rpy="1.5707963267948966 0 0" xyz="0 0 0" />
            <geometry>
                <cylinder length="0.032" radius="0.0625" />
            </geometry>
            <material name="black">
                <color rgba="0.1 0.1 0.1 1" />
            </material>
        </visual>
        <collision>
            <origin rpy="1.5707963267948966 0 0" xyz="0 0 0" />
            <geometry>
                <cylinder length="0.032" radius="0.0625" />
            </geometry>
        </collision>
    </link>
    <gazebo reference="mir_right_wheel_link">
        <material>Gazebo/FlatBlack</material>
    </gazebo>
    <!-- caster hub -->
    <joint name="mir_fl_caster_rotation_joint" type="continuous">
        <origin rpy="0 0 0" xyz="0.34134600000000004 0.203 0.1565" />
        <parent link="mir_base_link" />
        <child link="mir_fl_caster_rotation_link" />
        <axis xyz="0 0 1" />
        <dynamics damping="0.01" friction="0.0" />
    </joint>
    <link name="mir_fl_caster_rotation_link">
        <inertial>
            <!-- <origin xyz="0 0 -0.042500000044" rpy="${0.5 * pi} ${24 * deg_to_rad} ${1.5 * pi}" /> -->
            <origin rpy="0.41887903200000004 0 1.5707963267948966 " xyz="0 0 -0.042500000044" />
            <mass value="0.3097539019" />
            <inertia ixx="0.0005844517978" ixy="0" ixz="0" iyy="0.00052872551237" iyz="0" izz="0.00017923555074" />
        </inertial>
        <visual>
            <origin rpy="0 0 0" xyz="0 0 0" />
            <geometry>
                <mesh filename="package://mir_description/meshes/visual/caster_wheel_base.stl" />
            </geometry>
            <material name="silver">
                <color rgba="0.79 0.82 0.93 1" />
            </material>
        </visual>
        <collision>
            <origin rpy="0 0 0" xyz="0 0 0" />
            <geometry>
                <mesh filename="package://mir_description/meshes/collision/caster_wheel_base.stl" />
            </geometry>
        </collision>
    </link>
    <gazebo reference="mir_fl_caster_rotation_link">
        <material>Gazebo/Grey</material>
    </gazebo>
    <!-- caster wheel -->
    <joint name="mir_fl_caster_wheel_joint" type="continuous">
        <origin rpy="0 0 0" xyz="-0.0382 0 -0.094" />
        <parent link="mir_fl_caster_rotation_link" />
        <child link="mir_fl_caster_wheel_link" />
        <axis xyz="0 1 0" />
    </joint>
    <link name="mir_fl_caster_wheel_link">
        <inertial>
            <mass value="1.0" />
            <origin rpy="1.5707963267948966 0 0" xyz="0 0 0" />
            <inertia ixx="0.001061895408575" ixy="0.0" ixz="0.0" iyy="0.001061895408575" iyz="0.0" izz="0.001953125" />
        </inertial>
        <visual>
            <origin rpy="1.5707963267948966 0 0" xyz="0 0 0" />
            <geometry>
                <cylinder length="0.032" radius="0.0625" />
            </geometry>
            <material name="black">
                <color rgba="0.1 0.1 0.1 1" />
            </material>
        </visual>
        <collision>
            <origin rpy="1.5707963267948966 0 0" xyz="0 0 0" />
            <geometry>
                <cylinder length="0.032" radius="0.0625" />
            </geometry>
        </collision>
    </link>
    <gazebo reference="mir_fl_caster_wheel_link">
        <material>Gazebo/FlatBlack</material>
    </gazebo>
    <!-- caster hub -->
    <joint name="mir_fr_caster_rotation_joint" type="continuous">
        <origin rpy="0 0 0" xyz="0.34134600000000004 -0.203 0.1565" />
        <parent link="mir_base_link" />
        <child link="mir_fr_caster_rotation_link" />
        <axis xyz="0 0 1" />
        <dynamics damping="0.01" friction="0.0" />
    </joint>
    <link name="mir_fr_caster_rotation_link">
        <inertial>
            <!-- <origin xyz="0 0 -0.042500000044" rpy="${0.5 * pi} ${24 * deg_to_rad} ${1.5 * pi}" /> -->
            <origin rpy="0.41887903200000004 0 1.5707963267948966 " xyz="0 0 -0.042500000044" />
            <mass value="0.3097539019" />
            <inertia ixx="0.0005844517978" ixy="0" ixz="0" iyy="0.00052872551237" iyz="0" izz="0.00017923555074" />
        </inertial>
        <visual>
            <origin rpy="0 0 0" xyz="0 0 0" />
            <geometry>
                <mesh filename="package://mir_description/meshes/visual/caster_wheel_base.stl" />
            </geometry>
            <material name="silver">
                <color rgba="0.79 0.82 0.93 1" />
            </material>
        </visual>
        <collision>
            <origin rpy="0 0 0" xyz="0 0 0" />
            <geometry>
                <mesh filename="package://mir_description/meshes/collision/caster_wheel_base.stl" />
            </geometry>
        </collision>
    </link>
    <gazebo reference="mir_fr_caster_rotation_link">
        <material>Gazebo/Grey</material>
    </gazebo>
    <!-- caster wheel -->
    <joint name="mir_fr_caster_wheel_joint" type="continuous">
        <origin rpy="0 0 0" xyz="-0.0382 0 -0.094" />
        <parent link="mir_fr_caster_rotation_link" />
        <child link="mir_fr_caster_wheel_link" />
        <axis xyz="0 1 0" />
    </joint>
    <link name="mir_fr_caster_wheel_link">
        <inertial>
            <mass value="1.0" />
            <origin rpy="1.5707963267948966 0 0" xyz="0 0 0" />
            <inertia ixx="0.001061895408575" ixy="0.0" ixz="0.0" iyy="0.001061895408575" iyz="0.0" izz="0.001953125" />
        </inertial>
        <visual>
            <origin rpy="1.5707963267948966 0 0" xyz="0 0 0" />
            <geometry>
                <cylinder length="0.032" radius="0.0625" />
            </geometry>
            <material name="black">
                <color rgba="0.1 0.1 0.1 1" />
            </material>
        </visual>
        <collision>
            <origin rpy="1.5707963267948966 0 0" xyz="0 0 0" />
            <geometry>
                <cylinder length="0.032" radius="0.0625" />
            </geometry>
        </collision>
    </link>
    <gazebo reference="mir_fr_caster_wheel_link">
        <material>Gazebo/FlatBlack</material>
    </gazebo>
    <!-- caster hub -->
    <joint name="mir_bl_caster_rotation_joint" type="continuous">
        <origin rpy="0 0 0" xyz="-0.270154 0.203 0.1565" />
        <parent link="mir_base_link" />
        <child link="mir_bl_caster_rotation_link" />
        <axis xyz="0 0 1" />
        <dynamics damping="0.01" friction="0.0" />
    </joint>
    <link name="mir_bl_caster_rotation_link">
        <inertial>
            <!-- <origin xyz="0 0 -0.042500000044" rpy="${0.5 * pi} ${24 * deg_to_rad} ${1.5 * pi}" /> -->
            <origin rpy="0.41887903200000004 0 1.5707963267948966 " xyz="0 0 -0.042500000044" />
            <mass value="0.3097539019" />
            <inertia ixx="0.0005844517978" ixy="0" ixz="0" iyy="0.00052872551237" iyz="0" izz="0.00017923555074" />
        </inertial>
        <visual>
            <origin rpy="0 0 0" xyz="0 0 0" />
            <geometry>
                <mesh filename="package://mir_description/meshes/visual/caster_wheel_base.stl" />
            </geometry>
            <material name="silver">
                <color rgba="0.79 0.82 0.93 1" />
            </material>
        </visual>
        <collision>
            <origin rpy="0 0 0" xyz="0 0 0" />
            <geometry>
                <mesh filename="package://mir_description/meshes/collision/caster_wheel_base.stl" />
            </geometry>
        </collision>
    </link>
    <gazebo reference="mir_bl_caster_rotation_link">
        <material>Gazebo/Grey</material>
    </gazebo>
    <!-- caster wheel -->
    <joint name="mir_bl_caster_wheel_joint" type="continuous">
        <origin rpy="0 0 0" xyz="-0.0382 0 -0.094" />
        <parent link="mir_bl_caster_rotation_link" />
        <child link="mir_bl_caster_wheel_link" />
        <axis xyz="0 1 0" />
    </joint>
    <link name="mir_bl_caster_wheel_link">
        <inertial>
            <mass value="1.0" />
            <origin rpy="1.5707963267948966 0 0" xyz="0 0 0" />
            <inertia ixx="0.001061895408575" ixy="0.0" ixz="0.0" iyy="0.001061895408575" iyz="0.0" izz="0.001953125" />
        </inertial>
        <visual>
            <origin rpy="1.5707963267948966 0 0" xyz="0 0 0" />
            <geometry>
                <cylinder length="0.032" radius="0.0625" />
            </geometry>
            <material name="black">
                <color rgba="0.1 0.1 0.1 1" />
            </material>
        </visual>
        <collision>
            <origin rpy="1.5707963267948966 0 0" xyz="0 0 0" />
            <geometry>
                <cylinder length="0.032" radius="0.0625" />
            </geometry>
        </collision>
    </link>
    <gazebo reference="mir_bl_caster_wheel_link">
        <material>Gazebo/FlatBlack</material>
    </gazebo>
    <!-- caster hub -->
    <joint name="mir_br_caster_rotation_joint" type="continuous">
        <origin rpy="0 0 0" xyz="-0.270154 -0.203 0.1565" />
        <parent link="mir_base_link" />
        <child link="mir_br_caster_rotation_link" />
        <axis xyz="0 0 1" />
        <dynamics damping="0.01" friction="0.0" />
    </joint>
    <link name="mir_br_caster_rotation_link">
        <inertial>
            <!-- <origin xyz="0 0 -0.042500000044" rpy="${0.5 * pi} ${24 * deg_to_rad} ${1.5 * pi}" /> -->
            <origin rpy="0.41887903200000004 0 1.5707963267948966 " xyz="0 0 -0.042500000044" />
            <mass value="0.3097539019" />
            <inertia ixx="0.0005844517978" ixy="0" ixz="0" iyy="0.00052872551237" iyz="0" izz="0.00017923555074" />
        </inertial>
        <visual>
            <origin rpy="0 0 0" xyz="0 0 0" />
            <geometry>
                <mesh filename="package://mir_description/meshes/visual/caster_wheel_base.stl" />
            </geometry>
            <material name="silver">
                <color rgba="0.79 0.82 0.93 1" />
            </material>
        </visual>
        <collision>
            <origin rpy="0 0 0" xyz="0 0 0" />
            <geometry>
                <mesh filename="package://mir_description/meshes/collision/caster_wheel_base.stl" />
            </geometry>
        </collision>
    </link>
    <gazebo reference="mir_br_caster_rotation_link">
        <material>Gazebo/Grey</material>
    </gazebo>
    <!-- caster wheel -->
    <joint name="mir_br_caster_wheel_joint" type="continuous">
        <origin rpy="0 0 0" xyz="-0.0382 0 -0.094" />
        <parent link="mir_br_caster_rotation_link" />
        <child link="mir_br_caster_wheel_link" />
        <axis xyz="0 1 0" />
    </joint>
    <link name="mir_br_caster_wheel_link">
        <inertial>
            <mass value="1.0" />
            <origin rpy="1.5707963267948966 0 0" xyz="0 0 0" />
            <inertia ixx="0.001061895408575" ixy="0.0" ixz="0.0" iyy="0.001061895408575" iyz="0.0" izz="0.001953125" />
        </inertial>
        <visual>
            <origin rpy="1.5707963267948966 0 0" xyz="0 0 0" />
            <geometry>
                <cylinder length="0.032" radius="0.0625" />
            </geometry>
            <material name="black">
                <color rgba="0.1 0.1 0.1 1" />
            </material>
        </visual>
        <collision>
            <origin rpy="1.5707963267948966 0 0" xyz="0 0 0" />
            <geometry>
                <cylinder length="0.032" radius="0.0625" />
            </geometry>
        </collision>
    </link>
    <gazebo reference="mir_br_caster_wheel_link">
        <material>Gazebo/FlatBlack</material>
    </gazebo>
    <joint name="mir_base_link_surface_joint" type="fixed">
        <origin rpy="0 0 0" xyz="0.037646 0 0.352" />
        <parent link="mir_base_link" />
        <child link="mir_surface" />
        <axis xyz="0 0 1" />
    </joint>
    <link name="mir_surface" />
    <transmission name="mir_left_wheel_trans">
        <type>transmission_interface/SimpleTransmission</type>
        <joint name="mir_left_wheel_joint">
            <hardwareInterface>hardware_interface/VelocityJointInterface</hardwareInterface>
        </joint>
        <actuator name="mir_left_wheel_motor">
            <hardwareInterface>hardware_interface/VelocityJointInterface</hardwareInterface>
            <mechanicalReduction>1</mechanicalReduction>
        </actuator>
    </transmission>
    <transmission name="mir_right_wheel_trans">
        <type>transmission_interface/SimpleTransmission</type>
        <joint name="mir_right_wheel_joint">
            <hardwareInterface>hardware_interface/VelocityJointInterface</hardwareInterface>
        </joint>
        <actuator name="mir_right_wheel_motor">
            <hardwareInterface>hardware_interface/VelocityJointInterface</hardwareInterface>
            <mechanicalReduction>1</mechanicalReduction>
        </actuator>
    </transmission>
    <gazebo reference="mir_left_wheel_link">
        <mu1 value="200" />
        <mu2 value="200" />
        <kp value="10000000.0" />
        <kd value="1.0" />
        <minDepth>0.01</minDepth>
    </gazebo>
    <gazebo reference="mir_right_wheel_link">
        <mu1 value="200" />
        <mu2 value="200" />
        <kp value="10000000.0" />
        <kd value="1.0" />
        <minDepth>0.01</minDepth>
    </gazebo>
    <gazebo reference="mir_fl_caster_wheel_link">
        <mu1 value="1" />
        <mu2 value="1" />
        <kp value="10000000.0" />
        <kd value="1.0" />
        <minDepth>0.01</minDepth>
    </gazebo>
    <gazebo reference="mir_fr_caster_wheel_link">
        <mu1 value="1" />
        <mu2 value="1" />
        <kp value="10000000.0" />
        <kd value="1.0" />
        <minDepth>0.01</minDepth>
    </gazebo>
    <gazebo reference="mir_bl_caster_wheel_link">
        <mu1 value="1" />
        <mu2 value="1" />
        <kp value="10000000.0" />
        <kd value="1.0" />
        <minDepth>0.01</minDepth>
    </gazebo>
    <gazebo reference="mir_br_caster_wheel_link">
        <mu1 value="1" />
        <mu2 value="1" />
        <kp value="10000000.0" />
        <kd value="1.0" />
        <minDepth>0.01</minDepth>
    </gazebo>
    <gazebo>
        <plugin filename="libgazebo_ros_p3d.so" name="p3d_base_controller">
            <alwaysOn>true</alwaysOn>
            <updateRate>50.0</updateRate>
            <bodyName>mir_base_footprint</bodyName>
            <topicName>base_pose_ground_truth</topicName>
            <gaussianNoise>0.01</gaussianNoise>
            <frameName>map</frameName>
            <xyzOffsets>0 0 0</xyzOffsets>
            <rpyOffsets>0 0 0</rpyOffsets>
        </plugin>
    </gazebo>
    <!-- === Structure === -->
    <link name="butler_structure">
        <visual>
            <origin rpy="0 0 0" xyz="0 0 0" />
            <geometry>
                <mesh filename="package://butler_description/meshes/body/visual/body.obj" scale="0.001 0.001 0.001" />
            </geometry>
        </visual>
        <collision>
            <origin rpy="-1.5707963267948966 0 -1.5707963267948966" xyz="0 0.271 0.270" />
            <geometry>
                <mesh filename="package://butler_description/meshes/body/collision/body.stl" />
            </geometry>
        </collision>
        <inertial>
            <mass value="0.1" />
            <origin xyz="0 0 0" rpy="0 0 0" />
            <inertia ixx="0.03" iyy="0.03" izz="0.03" ixy="0.0" ixz="0.0" iyz="0.0" />
        </inertial>
    </link>
    <!-- === Logo === -->
    <link name="cover_left">
        <visual>
            <origin rpy="0 0 0" xyz="0 0 0" />
            <geometry>
                <mesh filename="package://butler_description/meshes/body/visual/cover_left_with_logo.dae" />
            </geometry>
        </visual>
        <collision>
            <origin rpy="0 0 0" xyz="0 0 0" />
            <geometry>
                <mesh filename="package://butler_description/meshes/body/visual/cover_left_with_logo.dae" />
            </geometry>
        </collision>
        <inertial>
            <mass value="0.1" />
            <origin xyz="0 0 0" rpy="0 0 0" />
            <inertia ixx="0.03" iyy="0.03" izz="0.03" ixy="0.0" ixz="0.0" iyz="0.0" />
        </inertial>
    </link>
    <!-- joint logo cover with butler body -->
    <joint name="cover_left_joint" type="fixed">
        <origin rpy="0 0 1.5707963267948966" xyz="-0.378 0.5405000000000001 0.27" />
        <parent link="butler_structure" />
        <child link="cover_left" />
    </joint>
    <!-- === Gazebo === 
  <xacro:include filename="$(find butler_description)/urdf/butler/butler.gazebo.xacro" />
  <xacro:butler_gazebo prefix="${prefix}" robot_namespace="" />
  -->
    <!--
    Base UR robot series xacro macro.

    NOTE: this is NOT a URDF. It cannot directly be loaded by consumers
    expecting a flattened '.urdf' file. See the top-level '.xacro' for that
    (but note: that .xacro must still be processed by the xacro command).

    For use in '.launch' files: use one of the 'load_urX.launch' convenience
    launch files.

    This file models the base kinematic chain of a UR robot, which then gets
    parameterised by various configuration files to convert it into a UR3(e),
    UR5(e), UR10(e) or UR16e.

    NOTE: the default kinematic parameters (ie: link lengths, frame locations,
    offets, etc) do not correspond to any particular robot. They are defaults
    only. There WILL be non-zero offsets between the Forward Kinematics results
    in TF (ie: robot_state_publisher) and the values reported by the Teach
    Pendant.

    For accurate (and robot-specific) transforms, the 'kinematics_parameters_file'
    parameter MUST point to a .yaml file containing the appropriate values for
    the targetted robot.

    If using the UniversalRobots/Universal_Robots_ROS_Driver, follow the steps
    described in the readme of that repository to extract the kinematic
    calibration from the controller and generate the required .yaml file.

    Main author of the migration to yaml configs: Ludovic Delval.

    Contributors to previous versions (in no particular order):

     - Felix Messmer
     - Kelsey Hawkins
     - Wim Meeussen
     - Shaun Edwards
     - Nadia Hammoudeh Garcia
     - Dave Hershberger
     - G. vd. Hoorn
     - Philip Long
     - Dave Coleman
     - Miguel Prada
     - Mathias Luedtke
     - Marcel Schnirring
     - Felix von Drigalski
     - Felix Exner
     - Jimmy Da Silva
     - Ajit Krisshna N L
     - Muhammad Asif Rana
  -->
    <!--
    NOTE: the macro defined in this file is NOT part of the public API of this
          package. Users CANNOT rely on this file being available, or stored in
          this location. Nor can they rely on the existence of the macro.
  -->
    <transmission name="shoulder_pan_trans">
        <type>transmission_interface/SimpleTransmission</type>
        <joint name="shoulder_pan_joint">
            <hardwareInterface>hardware_interface/PositionJointInterface</hardwareInterface>
        </joint>
        <actuator name="shoulder_pan_motor">
            <mechanicalReduction>1</mechanicalReduction>
            <hardwareInterface>hardware_interface/EffortJointInterface</hardwareInterface>
        </actuator>
    </transmission>
    <transmission name="shoulder_lift_trans">
        <type>transmission_interface/SimpleTransmission</type>
        <joint name="shoulder_lift_joint">
            <hardwareInterface>hardware_interface/PositionJointInterface</hardwareInterface>
        </joint>
        <actuator name="shoulder_lift_motor">
            <mechanicalReduction>1</mechanicalReduction>
            <hardwareInterface>hardware_interface/EffortJointInterface</hardwareInterface>
        </actuator>
    </transmission>
    <transmission name="elbow_trans">
        <type>transmission_interface/SimpleTransmission</type>
        <joint name="elbow_joint">
            <hardwareInterface>hardware_interface/PositionJointInterface</hardwareInterface>
        </joint>
        <actuator name="elbow_motor">
            <mechanicalReduction>1</mechanicalReduction>
            <hardwareInterface>hardware_interface/EffortJointInterface</hardwareInterface>
        </actuator>
    </transmission>
    <transmission name="wrist_1_trans">
        <type>transmission_interface/SimpleTransmission</type>
        <joint name="wrist_1_joint">
            <hardwareInterface>hardware_interface/PositionJointInterface</hardwareInterface>
        </joint>
        <actuator name="wrist_1_motor">
            <mechanicalReduction>1</mechanicalReduction>
            <hardwareInterface>hardware_interface/EffortJointInterface</hardwareInterface>
        </actuator>
    </transmission>
    <transmission name="wrist_2_trans">
        <type>transmission_interface/SimpleTransmission</type>
        <joint name="wrist_2_joint">
            <hardwareInterface>hardware_interface/PositionJointInterface</hardwareInterface>
        </joint>
        <actuator name="wrist_2_motor">
            <mechanicalReduction>1</mechanicalReduction>
            <hardwareInterface>hardware_interface/EffortJointInterface</hardwareInterface>
        </actuator>
    </transmission>
    <transmission name="wrist_3_trans">
        <type>transmission_interface/SimpleTransmission</type>
        <joint name="wrist_3_joint">
            <hardwareInterface>hardware_interface/PositionJointInterface</hardwareInterface>
        </joint>
        <actuator name="wrist_3_motor">
            <mechanicalReduction>1</mechanicalReduction>
            <hardwareInterface>hardware_interface/EffortJointInterface</hardwareInterface>
        </actuator>
    </transmission>
    <!-- links: main serial chain -->
    <link name="base_link" />
    <link name="base_link_inertia">
        <visual>
            <origin rpy="0 0 3.141592653589793" xyz="0 0 0" />
            <geometry>
                <mesh filename="package://ur_description/meshes/ur5/visual/base.dae" />
            </geometry>
            <material name="LightGrey">
                <color rgba="0.7 0.7 0.7 1.0" />
            </material>
        </visual>
        <collision>
            <origin rpy="0 0 3.141592653589793" xyz="0 0 0" />
            <geometry>
                <mesh filename="package://ur_description/meshes/ur5/collision/base.stl" />
            </geometry>
        </collision>
        <inertial>
            <mass value="4.0" />
            <origin rpy="0 0 0" xyz="0 0 0" />
            <inertia ixx="0.00443333156" ixy="0.0" ixz="0.0" iyy="0.00443333156" iyz="0.0" izz="0.0072" />
        </inertial>
    </link>
    <link name="shoulder_link">
        <visual>
            <origin rpy="0 0 3.141592653589793" xyz="0 0 0" />
            <geometry>
                <mesh filename="package://ur_description/meshes/ur5/visual/shoulder.dae" />
            </geometry>
            <material name="LightGrey">
                <color rgba="0.7 0.7 0.7 1.0" />
            </material>
        </visual>
        <collision>
            <origin rpy="0 0 3.141592653589793" xyz="0 0 0" />
            <geometry>
                <mesh filename="package://ur_description/meshes/ur5/collision/shoulder.stl" />
            </geometry>
        </collision>
        <inertial>
            <mass value="3.7" />
            <origin rpy="0 0 0" xyz="0 0 0" />
            <inertia ixx="0.014972352344389999" ixy="0.0" ixz="0.0" iyy="0.014972352344389999" iyz="0.0" izz="0.01040625" />
        </inertial>
    </link>
    <link name="upper_arm_link">
        <visual>
            <origin rpy="1.5707963267948966 0 -1.5707963267948966" xyz="0 0 0.13585" />
            <geometry>
                <mesh filename="package://ur_description/meshes/ur5/visual/upperarm.dae" />
            </geometry>
            <material name="LightGrey">
                <color rgba="0.7 0.7 0.7 1.0" />
            </material>
        </visual>
        <collision>
            <origin rpy="1.5707963267948966 0 -1.5707963267948966" xyz="0 0 0.13585" />
            <geometry>
                <mesh filename="package://ur_description/meshes/ur5/collision/upperarm.stl" />
            </geometry>
        </collision>
        <inertial>
            <mass value="8.393" />
            <origin rpy="0 1.5707963267948966 0" xyz="-0.2125 0.0 0.136" />
            <inertia ixx="0.1338857818623325" ixy="0.0" ixz="0.0" iyy="0.1338857818623325" iyz="0.0" izz="0.0151074" />
        </inertial>
    </link>
    <link name="forearm_link">
        <visual>
            <origin rpy="1.5707963267948966 0 -1.5707963267948966" xyz="0 0 0.0165" />
            <geometry>
                <mesh filename="package://ur_description/meshes/ur5/visual/forearm.dae" />
            </geometry>
            <material name="LightGrey">
                <color rgba="0.7 0.7 0.7 1.0" />
            </material>
        </visual>
        <collision>
            <origin rpy="1.5707963267948966 0 -1.5707963267948966" xyz="0 0 0.0165" />
            <geometry>
                <mesh filename="package://ur_description/meshes/ur5/collision/forearm.stl" />
            </geometry>
        </collision>
        <inertial>
            <mass value="2.275" />
            <origin rpy="0 1.5707963267948966 0" xyz="-0.196125 0.0 0.0165" />
            <inertia ixx="0.03121679102890359" ixy="0.0" ixz="0.0" iyy="0.03121679102890359" iyz="0.0" izz="0.004095" />
        </inertial>
    </link>
    <link name="wrist_1_link">
        <visual>
            <!-- TODO: Move this to a parameter -->
            <origin rpy="1.5707963267948966 0 0" xyz="0 0 -0.093" />
            <geometry>
                <mesh filename="package://ur_description/meshes/ur5/visual/wrist1.dae" />
            </geometry>
            <material name="LightGrey">
                <color rgba="0.7 0.7 0.7 1.0" />
            </material>
        </visual>
        <collision>
            <origin rpy="1.5707963267948966 0 0" xyz="0 0 -0.093" />
            <geometry>
                <mesh filename="package://ur_description/meshes/ur5/collision/wrist1.stl" />
            </geometry>
        </collision>
        <inertial>
            <mass value="1.219" />
            <origin rpy="0 0 0" xyz="0 0 0" />
            <inertia ixx="0.0020138887777775" ixy="0.0" ixz="0.0" iyy="0.0020138887777775" iyz="0.0" izz="0.0021942" />
        </inertial>
    </link>
    <link name="wrist_2_link">
        <visual>
            <origin rpy="0 0 0" xyz="0 0 -0.095" />
            <geometry>
                <mesh filename="package://ur_description/meshes/ur5/visual/wrist2.dae" />
            </geometry>
            <material name="LightGrey">
                <color rgba="0.7 0.7 0.7 1.0" />
            </material>
        </visual>
        <collision>
            <origin rpy="0 0 0" xyz="0 0 -0.095" />
            <geometry>
                <mesh filename="package://ur_description/meshes/ur5/collision/wrist2.stl" />
            </geometry>
        </collision>
        <inertial>
            <mass value="1.219" />
            <origin rpy="0 0 0" xyz="0 0 0" />
            <inertia ixx="0.0018310388509175" ixy="0.0" ixz="0.0" iyy="0.0018310388509175" iyz="0.0" izz="0.0021942" />
        </inertial>
    </link>
    <link name="wrist_3_link">
        <visual>
            <origin rpy="1.5707963267948966 0 0" xyz="0 0 -0.0818" />
            <geometry>
                <mesh filename="package://ur_description/meshes/ur5/visual/wrist3.dae" />
            </geometry>
            <material name="LightGrey">
                <color rgba="0.7 0.7 0.7 1.0" />
            </material>
        </visual>
        <collision>
            <origin rpy="1.5707963267948966 0 0" xyz="0 0 -0.0818" />
            <geometry>
                <mesh filename="package://ur_description/meshes/ur5/collision/wrist3.stl" />
            </geometry>
        </collision>
        <inertial>
            <mass value="0.1879" />
            <origin rpy="0 0 0" xyz="0.0 0.0 -0.01525" />
            <inertia ixx="8.062472608343e-05" ixy="0.0" ixz="0.0" iyy="8.062472608343e-05" iyz="0.0" izz="0.0001321171875" />
        </inertial>
    </link>
    <!-- joints: main serial chain -->
    <joint name="base_link-base_link_inertia" type="fixed">
        <parent link="base_link" />
        <child link="base_link_inertia" />
        <!-- 'base_link' is REP-103 aligned (so X+ forward), while the internal
           frames of the robot/controller have X+ pointing backwards.
           Use the joint between 'base_link' and 'base_link_inertia' (a dummy
           link/frame) to introduce the necessary rotation over Z (of pi rad).
      -->
        <origin rpy="0 0 3.141592653589793" xyz="0 0 0" />
    </joint>
    <joint name="shoulder_pan_joint" type="revolute">
        <parent link="base_link_inertia" />
        <child link="shoulder_link" />
        <origin rpy="0 0 0" xyz="0 0 0.089159" />
        <axis xyz="0 0 1" />
        <limit effort="150.0" lower="-6.283185307179586" upper="6.283185307179586" velocity="3.141592653589793" />
        <dynamics damping="0" friction="0" />
    </joint>
    <joint name="shoulder_lift_joint" type="revolute">
        <parent link="shoulder_link" />
        <child link="upper_arm_link" />
        <origin rpy="1.570796327 0 0" xyz="0 0 0" />
        <axis xyz="0 0 1" />
        <limit effort="150.0" lower="-6.283185307179586" upper="6.283185307179586" velocity="3.141592653589793" />
        <dynamics damping="0" friction="0" />
    </joint>
    <joint name="elbow_joint" type="revolute">
        <parent link="upper_arm_link" />
        <child link="forearm_link" />
        <origin rpy="0 0 0" xyz="-0.425 0 0" />
        <axis xyz="0 0 1" />
        <limit effort="150.0" lower="-3.141592653589793" upper="3.141592653589793" velocity="3.141592653589793" />
        <dynamics damping="0" friction="0" />
    </joint>
    <joint name="wrist_1_joint" type="revolute">
        <parent link="forearm_link" />
        <child link="wrist_1_link" />
        <origin rpy="0 0 0" xyz="-0.39225 0 0.10915" />
        <axis xyz="0 0 1" />
        <limit effort="28.0" lower="-6.283185307179586" upper="6.283185307179586" velocity="3.141592653589793" />
        <dynamics damping="0" friction="0" />
    </joint>
    <joint name="wrist_2_joint" type="revolute">
        <parent link="wrist_1_link" />
        <child link="wrist_2_link" />
        <origin rpy="1.570796327 0 0" xyz="0 -0.09465 -1.941303950897609e-11" />
        <axis xyz="0 0 1" />
        <limit effort="28.0" lower="-6.283185307179586" upper="6.283185307179586" velocity="3.141592653589793" />
        <dynamics damping="0" friction="0" />
    </joint>
    <joint name="wrist_3_joint" type="revolute">
        <parent link="wrist_2_link" />
        <child link="wrist_3_link" />
        <origin rpy="1.570796326589793 3.141592653589793 3.141592653589793" xyz="0 0.0823 -1.688001216681175e-11" />
        <axis xyz="0 0 1" />
        <limit effort="28.0" lower="-6.283185307179586" upper="6.283185307179586" velocity="3.141592653589793" />
        <dynamics damping="0" friction="0" />
    </joint>
    <!-- ROS-Industrial 'base' frame: base_link to UR 'Base' Coordinates transform -->
    <link name="base" />
    <joint name="base_link-base_fixed_joint" type="fixed">
        <!-- Note the rotation over Z of pi radians: as base_link is REP-103
           aligned (ie: has X+ forward, Y+ left and Z+ up), this is needed
           to correctly align 'base' with the 'Base' coordinate system of
           the UR controller.
      -->
        <origin rpy="0 0 3.141592653589793" xyz="0 0 0" />
        <parent link="base_link" />
        <child link="base" />
    </joint>
    <!-- ROS-Industrial 'flange' frame: attachment point for EEF models -->
    <link name="flange" />
    <joint name="wrist_3-flange" type="fixed">
        <parent link="wrist_3_link" />
        <child link="flange" />
        <origin rpy="0 -1.5707963267948966 -1.5707963267948966" xyz="0 0 0" />
    </joint>
    <!-- ROS-Industrial 'tool0' frame: all-zeros tool frame -->
    <link name="tool0" />
    <joint name="flange-tool0" type="fixed">
        <!-- default toolframe: X+ left, Y+ up, Z+ front -->
        <origin rpy="1.5707963267948966 0 1.5707963267948966" xyz="0 0 0" />
        <parent link="flange" />
        <child link="tool0" />
    </joint>
    <link name="kamerahalterung">
        <inertial>
            <origin rpy="0 0 0" xyz="-0.038021 7.5933E-19 0.0031873" />
            <mass value="0.05" />
            <inertia ixx="1.9359E-05" ixy="2.4161E-21" ixz="-1.3664E-06" iyy="8.4124E-05" iyz="1.1107E-22" izz="0.00010304" />
        </inertial>
        <visual>
            <origin rpy="0 0 0" xyz="0 0 0" />
            <geometry>
                <mesh filename="package://gripper_2F_85_description/meshes/kamerahalterung.STL" />
            </geometry>
            <material name="">
                <color rgba="0.1 0.1 0.1 1" />
            </material>
        </visual>
        <collision>
            <origin rpy="0 0 0" xyz="0 0 0" />
            <geometry>
                <mesh filename="package://gripper_2F_85_description/meshes/kamerahalterung.STL" />
            </geometry>
        </collision>
    </link>
    <link name="Kamera_Basis_KS" />
    <joint name="fixed_link_to_Kamera" type="fixed">
        <origin rpy="0 0 0" xyz="-0.0945 0 0.005" />
        <parent link="kamerahalterung" />
        <child link="Kamera_Basis_KS" />
    </joint>
    <link name="flanschplatte">
        <visual>
            <origin rpy="0 0 0" xyz="0 0 0" />
            <geometry>
                <mesh filename="package://gripper_2F_85_description/meshes/visual/robotiq_gripper_coupling.stl" scale="0.001 0.001 0.001" />
            </geometry>
            <material name="">
                <color rgba="0.1 0.1 0.1 1" />
            </material>
        </visual>
        <collision>
            <origin rpy="0 0 0" xyz="0 0 0" />
            <geometry>
                <mesh filename="package://gripper_2F_85_description/meshes/visual/robotiq_gripper_coupling.stl" scale="0.001 0.001 0.001" />
            </geometry>
        </collision>
        <inertial>
            <mass value="0.1" />
            <origin xyz="0 0 0" rpy="0 0 0" />
            <inertia ixx="0.03" iyy="0.03" izz="0.03" ixy="0.0" ixz="0.0" iyz="0.0" />
        </inertial>
    </link>
    <link name="robotiq_arg2f_base_link">
        <inertial>
            <origin rpy="0 0 0" xyz="8.625E-08 -4.6583E-06 0.03145" />
            <mass value="0.22652" />
            <inertia ixx="0.00020005" ixy="-4.2442E-10" ixz="-2.9069E-10" iyy="0.00017832" iyz="-3.4402E-08" izz="0.00013478" />
        </inertial>
        <visual>
            <origin rpy="0 0 0" xyz="0 0 0" />
            <geometry>
                <mesh filename="package://gripper_2F_85_description/meshes/visual/robotiq_arg2f_85_base_link.dae" scale="0.001 0.001 0.001" />
            </geometry>
            <material name="">
                <color rgba="0.1 0.1 0.1 1" />
            </material>
        </visual>
        <collision>
            <origin rpy="0 0 0" xyz="0 0 0" />
            <geometry>
                <mesh filename="package://gripper_2F_85_description/meshes/collision/robotiq_arg2f_base_link.stl" />
            </geometry>
        </collision>
    </link>
    <link name="left_outer_knuckle">
        <!--<inertial>
        <origin xyz="-0.000200000000003065 0.0199435877845359 0.0292245259211331" rpy="0 0 0" />
        <mass value="0.00853198276973456" />
        <inertia ixx="2.89328108496468E-06" ixy="-1.57935047237397E-19" ixz="-1.93980378593255E-19" iyy="1.86719750325683E-06" iyz="-1.21858577871576E-06" izz="1.21905238907251E-06" />
        </inertial> -->
        <visual>
            <origin rpy="0 0 0" xyz="0 0 0" />
            <geometry>
                <mesh filename="package://gripper_2F_85_description/meshes/visual/robotiq_arg2f_85_outer_knuckle.dae" scale="0.001 0.001 0.001" />
            </geometry>
            <material name="">
                <color rgba="0.792156862745098 0.819607843137255 0.933333333333333 1" />
            </material>
        </visual>
        <collision>
            <origin rpy="0 0 0" xyz="0 0 0" />
            <geometry>
                <mesh filename="package://gripper_2F_85_description/meshes/collision/robotiq_arg2f_85_outer_knuckle.dae" scale="0.001 0.001 0.001" />
            </geometry>
        </collision>
        <inertial>
            <mass value="0.1" />
            <origin xyz="0 0 0" rpy="0 0 0" />
            <inertia ixx="0.03" iyy="0.03" izz="0.03" ixy="0.0" ixz="0.0" iyz="0.0" />
        </inertial>
    </link>
    <link name="left_outer_finger">
        <!--<inertial>
        <origin xyz="0.00030115855001899 0.0373907951953854 -0.0208027427000385" rpy="0 0 0" />
        <mass value="0.022614240507152" />
        <inertia ixx="1.52518312458174E-05" ixy="9.76583423954399E-10" ixz="-5.43838577022588E-10" iyy="6.17694243867776E-06" iyz="6.78636130740228E-06" izz="1.16494917907219E-05" />
        </inertial> -->
        <visual>
            <origin rpy="0 0 0" xyz="0 0 0" />
            <geometry>
                <mesh filename="package://gripper_2F_85_description/meshes/visual/robotiq_arg2f_85_outer_finger.dae" scale="0.001 0.001 0.001" />
            </geometry>
            <material name="">
                <color rgba="0.1 0.1 0.1 1" />
            </material>
        </visual>
        <collision>
            <origin rpy="0 0 0" xyz="0 0 0" />
            <geometry>
                <mesh filename="package://gripper_2F_85_description/meshes/collision/robotiq_arg2f_85_outer_finger.dae" scale="0.001 0.001 0.001" />
            </geometry>
        </collision>
        <inertial>
            <mass value="0.1" />
            <origin xyz="0 0 0" rpy="0 0 0" />
            <inertia ixx="0.03" iyy="0.03" izz="0.03" ixy="0.0" ixz="0.0" iyz="0.0" />
        </inertial>
    </link>
    <link name="left_inner_finger">
        <!--<inertial>
        <origin xyz="0.000299999999999317 0.0160078233491243 -0.0136945669206257" rpy="0 0 0" />
        <mass value="0.0104003125914103" />
        <inertia ixx="2.71909453810972E-06" ixy="1.35402465472579E-21" ixz="-7.1817349065269E-22" iyy="7.69100314106116E-07" iyz="6.74715432769696E-07" izz="2.30315190420171E-06" />
        </inertial> -->
        <visual>
            <origin rpy="0 0 0" xyz="0 0 0" />
            <geometry>
                <mesh filename="package://gripper_2F_85_description/meshes/visual/robotiq_arg2f_85_inner_finger.dae" scale="0.001 0.001 0.001" />
            </geometry>
            <material name="">
                <color rgba="0.1 0.1 0.1 1" />
            </material>
        </visual>
        <collision>
            <origin rpy="0 0 0" xyz="0 0 0" />
            <geometry>
                <mesh filename="package://gripper_2F_85_description/meshes/collision/robotiq_arg2f_85_inner_finger.dae" scale="0.001 0.001 0.001" />
            </geometry>
        </collision>
        <inertial>
            <mass value="0.1" />
            <origin xyz="0 0 0" rpy="0 0 0" />
            <inertia ixx="0.03" iyy="0.03" izz="0.03" ixy="0.0" ixz="0.0" iyz="0.0" />
        </inertial>
    </link>
    <link name="left_inner_finger_pad">
        <visual>
            <origin rpy="0 0 0" xyz="0 0 0" />
            <geometry>
                <box size="0.022 0.00635 0.0375" />
            </geometry>
            <material name="">
                <color rgba="0.9 0.9 0.9 1" />
            </material>
        </visual>
        <collision>
            <origin rpy="0 0 0" xyz="0 0 0" />
            <geometry>
                <box size="0.022 0.00635 0.0375" />
            </geometry>
            <material name="">
                <color rgba="0.9 0.0 0.0 1" />
            </material>
        </collision>
        <inertial>
            <mass value="0.1" />
            <origin xyz="0 0 0" rpy="0 0 0" />
            <inertia ixx="0.03" iyy="0.03" izz="0.03" ixy="0.0" ixz="0.0" iyz="0.0" />
        </inertial>
    </link>
    <link name="left_inner_knuckle">
        <!--<inertial>
        <origin xyz="0.000123011831763771 0.0507850843201817 0.00103968640075166" rpy="0 0 0" />
       <mass value="0.0271177346495152" />
        <inertia ixx="2.61910379223783E-05" ixy="-2.43616858946494E-07" ixz="-6.37789906117123E-09" iyy="2.8270243746167E-06" iyz="-5.37200748039765E-07" izz="2.83695868220296E-05" />
        </inertial> -->
        <visual>
            <origin rpy="0 0 0" xyz="0 0 0" />
            <geometry>
                <mesh filename="package://gripper_2F_85_description/meshes/visual/robotiq_arg2f_85_inner_knuckle.dae" scale="0.001 0.001 0.001" />
            </geometry>
            <material name="">
                <color rgba="0.1 0.1 0.1 1" />
            </material>
        </visual>
        <collision>
            <origin rpy="0 0 0" xyz="0 0 0" />
            <geometry>
                <mesh filename="package://gripper_2F_85_description/meshes/collision/robotiq_arg2f_85_inner_knuckle.dae" scale="0.001 0.001 0.001" />
            </geometry>
        </collision>
        <inertial>
            <mass value="0.1" />
            <origin xyz="0 0 0" rpy="0 0 0" />
            <inertia ixx="0.03" iyy="0.03" izz="0.03" ixy="0.0" ixz="0.0" iyz="0.0" />
        </inertial>
    </link>
    <link name="right_outer_knuckle">
        <!--<inertial>
        <origin xyz="-0.000200000000003065 0.0199435877845359 0.0292245259211331" rpy="0 0 0" />
        <mass value="0.00853198276973456" />
        <inertia ixx="2.89328108496468E-06" ixy="-1.57935047237397E-19" ixz="-1.93980378593255E-19" iyy="1.86719750325683E-06" iyz="-1.21858577871576E-06" izz="1.21905238907251E-06" />
        </inertial> -->
        <visual>
            <origin rpy="0 0 0" xyz="0 0 0" />
            <geometry>
                <mesh filename="package://gripper_2F_85_description/meshes/visual/robotiq_arg2f_85_outer_knuckle.dae" scale="0.001 0.001 0.001" />
            </geometry>
            <material name="">
                <color rgba="0.792156862745098 0.819607843137255 0.933333333333333 1" />
            </material>
        </visual>
        <collision>
            <origin rpy="0 0 0" xyz="0 0 0" />
            <geometry>
                <mesh filename="package://gripper_2F_85_description/meshes/collision/robotiq_arg2f_85_outer_knuckle.dae" scale="0.001 0.001 0.001" />
            </geometry>
        </collision>
        <inertial>
            <mass value="0.1" />
            <origin xyz="0 0 0" rpy="0 0 0" />
            <inertia ixx="0.03" iyy="0.03" izz="0.03" ixy="0.0" ixz="0.0" iyz="0.0" />
        </inertial>
    </link>
    <link name="right_outer_finger">
        <!--<inertial>
        <origin xyz="0.00030115855001899 0.0373907951953854 -0.0208027427000385" rpy="0 0 0" />
        <mass value="0.022614240507152" />
        <inertia ixx="1.52518312458174E-05" ixy="9.76583423954399E-10" ixz="-5.43838577022588E-10" iyy="6.17694243867776E-06" iyz="6.78636130740228E-06" izz="1.16494917907219E-05" />
        </inertial> -->
        <visual>
            <origin rpy="0 0 0" xyz="0 0 0" />
            <geometry>
                <mesh filename="package://gripper_2F_85_description/meshes/visual/robotiq_arg2f_85_outer_finger.dae" scale="0.001 0.001 0.001" />
            </geometry>
            <material name="">
                <color rgba="0.1 0.1 0.1 1" />
            </material>
        </visual>
        <collision>
            <origin rpy="0 0 0" xyz="0 0 0" />
            <geometry>
                <mesh filename="package://gripper_2F_85_description/meshes/collision/robotiq_arg2f_85_outer_finger.dae" scale="0.001 0.001 0.001" />
            </geometry>
        </collision>
        <inertial>
            <mass value="0.1" />
            <origin xyz="0 0 0" rpy="0 0 0" />
            <inertia ixx="0.03" iyy="0.03" izz="0.03" ixy="0.0" ixz="0.0" iyz="0.0" />
        </inertial>
    </link>
    <link name="right_inner_finger">
        <!--<inertial>
        <origin xyz="0.000299999999999317 0.0160078233491243 -0.0136945669206257" rpy="0 0 0" />
        <mass value="0.0104003125914103" />
        <inertia ixx="2.71909453810972E-06" ixy="1.35402465472579E-21" ixz="-7.1817349065269E-22" iyy="7.69100314106116E-07" iyz="6.74715432769696E-07" izz="2.30315190420171E-06" />
        </inertial> -->
        <visual>
            <origin rpy="0 0 0" xyz="0 0 0" />
            <geometry>
                <mesh filename="package://gripper_2F_85_description/meshes/visual/robotiq_arg2f_85_inner_finger.dae" scale="0.001 0.001 0.001" />
            </geometry>
            <material name="">
                <color rgba="0.1 0.1 0.1 1" />
            </material>
        </visual>
        <collision>
            <origin rpy="0 0 0" xyz="0 0 0" />
            <geometry>
                <mesh filename="package://gripper_2F_85_description/meshes/collision/robotiq_arg2f_85_inner_finger.dae" scale="0.001 0.001 0.001" />
            </geometry>
        </collision>
        <inertial>
            <mass value="0.1" />
            <origin xyz="0 0 0" rpy="0 0 0" />
            <inertia ixx="0.03" iyy="0.03" izz="0.03" ixy="0.0" ixz="0.0" iyz="0.0" />
        </inertial>
    </link>
    <link name="right_inner_finger_pad">
        <visual>
            <origin rpy="0 0 0" xyz="0 0 0" />
            <geometry>
                <box size="0.022 0.00635 0.0375" />
            </geometry>
            <material name="">
                <color rgba="0.9 0.9 0.9 1" />
            </material>
        </visual>
        <collision>
            <origin rpy="0 0 0" xyz="0 0 0" />
            <geometry>
                <box size="0.022 0.00635 0.0375" />
            </geometry>
            <material name="">
                <color rgba="0.9 0.0 0.0 1" />
            </material>
        </collision>
        <inertial>
            <mass value="0.1" />
            <origin xyz="0 0 0" rpy="0 0 0" />
            <inertia ixx="0.03" iyy="0.03" izz="0.03" ixy="0.0" ixz="0.0" iyz="0.0" />
        </inertial>
    </link>
    <link name="right_inner_knuckle">
        <!--<inertial>
        <origin xyz="0.000123011831763771 0.0507850843201817 0.00103968640075166" rpy="0 0 0" />
       <mass value="0.0271177346495152" />
        <inertia ixx="2.61910379223783E-05" ixy="-2.43616858946494E-07" ixz="-6.37789906117123E-09" iyy="2.8270243746167E-06" iyz="-5.37200748039765E-07" izz="2.83695868220296E-05" />
        </inertial> -->
        <visual>
            <origin rpy="0 0 0" xyz="0 0 0" />
            <geometry>
                <mesh filename="package://gripper_2F_85_description/meshes/visual/robotiq_arg2f_85_inner_knuckle.dae" scale="0.001 0.001 0.001" />
            </geometry>
            <material name="">
                <color rgba="0.1 0.1 0.1 1" />
            </material>
        </visual>
        <collision>
            <origin rpy="0 0 0" xyz="0 0 0" />
            <geometry>
                <mesh filename="package://gripper_2F_85_description/meshes/collision/robotiq_arg2f_85_inner_knuckle.dae" scale="0.001 0.001 0.001" />
            </geometry>
        </collision>
        <inertial>
            <mass value="0.1" />
            <origin xyz="0 0 0" rpy="0 0 0" />
            <inertia ixx="0.03" iyy="0.03" izz="0.03" ixy="0.0" ixz="0.0" iyz="0.0" />
        </inertial>
    </link>
    <joint name="finger_joint" type="revolute">
        <origin rpy="0 0 3.141592653589793" xyz="0 -0.0306011 0.054904" />
        <parent link="robotiq_arg2f_base_link" />
        <child link="left_outer_knuckle" />
        <axis xyz="1 0 0" />
        <limit effort="1000" lower="0" upper="0.8" velocity="2.0" />
    </joint>
    <joint name="left_outer_finger_joint" type="fixed">
        <origin rpy="0 0 0" xyz="0 0.0315 -0.0041" />
        <parent link="left_outer_knuckle" />
        <child link="left_outer_finger" />
        <axis xyz="1 0 0" />
    </joint>
    <joint name="left_inner_knuckle_joint" type="revolute">
        <!-- <origin xyz="0 ${reflect * -0.0127} 0.06142" rpy="${pi / 2 + .725} 0 ${(reflect - 1) * pi / 2}" /> -->
        <origin rpy="0 0 3.141592653589793" xyz="0 -0.0127 0.06142" />
        <parent link="robotiq_arg2f_base_link" />
        <child link="left_inner_knuckle" />
        <axis xyz="1 0 0" />
        <limit effort="1000" lower="0" upper="0.8757" velocity="2.0" />
        <mimic joint="finger_joint" multiplier="1" offset="0" />
    </joint>
    <joint name="left_inner_finger_joint" type="revolute">
        <origin rpy="0 0 0" xyz="0 0.0061 0.0471" />
        <parent link="left_outer_finger" />
        <child link="left_inner_finger" />
        <axis xyz="1 0 0" />
        <limit effort="1000" lower="0" upper="0.8757" velocity="2.0" />
        <mimic joint="finger_joint" multiplier="-1" offset="0" />
    </joint>
    <joint name="left_inner_finger_pad_joint" type="fixed">
        <origin rpy="0 0 0" xyz="0 -0.0220203446692936 0.03242" />
        <parent link="left_inner_finger" />
        <child link="left_inner_finger_pad" />
        <axis xyz="0 0 1" />
    </joint>
    <joint name="right_outer_knuckle_joint" type="revolute">
        <origin rpy="0 0 0" xyz="0 0.0306011 0.054904" />
        <parent link="robotiq_arg2f_base_link" />
        <child link="right_outer_knuckle" />
        <axis xyz="1 0 0" />
        <limit effort="1000" lower="0" upper="0.81" velocity="2.0" />
        <mimic joint="finger_joint" multiplier="1" offset="0" />
    </joint>
    <joint name="right_outer_finger_joint" type="fixed">
        <origin rpy="0 0 0" xyz="0 0.0315 -0.0041" />
        <parent link="right_outer_knuckle" />
        <child link="right_outer_finger" />
        <axis xyz="1 0 0" />
    </joint>
    <joint name="right_inner_knuckle_joint" type="revolute">
        <!-- <origin xyz="0 ${reflect * -0.0127} 0.06142" rpy="${pi / 2 + .725} 0 ${(reflect - 1) * pi / 2}" /> -->
        <origin rpy="0 0 0.0" xyz="0 0.0127 0.06142" />
        <parent link="robotiq_arg2f_base_link" />
        <child link="right_inner_knuckle" />
        <axis xyz="1 0 0" />
        <limit effort="1000" lower="0" upper="0.8757" velocity="2.0" />
        <mimic joint="finger_joint" multiplier="1" offset="0" />
    </joint>
    <joint name="right_inner_finger_joint" type="revolute">
        <origin rpy="0 0 0" xyz="0 0.0061 0.0471" />
        <parent link="right_outer_finger" />
        <child link="right_inner_finger" />
        <axis xyz="1 0 0" />
        <limit effort="1000" lower="0" upper="0.8757" velocity="2.0" />
        <mimic joint="finger_joint" multiplier="-1" offset="0" />
    </joint>
    <joint name="right_inner_finger_pad_joint" type="fixed">
        <origin rpy="0 0 0" xyz="0 -0.0220203446692936 0.03242" />
        <parent link="right_inner_finger" />
        <child link="right_inner_finger_pad" />
        <axis xyz="0 0 1" />
    </joint>
    <transmission name="finger_joint_trans">
        <type>transmission_interface/SimpleTransmission</type>
        <joint name="finger_joint">
            <hardwareInterface>PositionJointInterface</hardwareInterface>
        </joint>
        <actuator name="finger_joint_motor">
            <mechanicalReduction>1</mechanicalReduction>
            <hardwareInterface>hardware_interface/EffortJointInterface</hardwareInterface>
        </actuator>
    </transmission>
    <link name="gripper_base" />
    <joint name="fixed_link_to_base" type="fixed">
        <origin rpy="0 0 0" xyz="0 0 0" />
        <parent link="gripper_base" />
        <child link="robotiq_arg2f_base_link" />
    </joint>
    <link name="gripper_tcp" />
    <joint name="fixed_link_to_tcp" type="fixed">
        <origin rpy="0 0 -1.57079632679" xyz="0 0 0.16" />
        <parent link="gripper_base" />
        <child link="gripper_tcp" />
    </joint>
    <!-- Verbindung zwischen Halterung und Greifer -->
    <joint name="fixed_link_to_fixture" type="fixed">
        <origin rpy="0 0 0" xyz="0 0 0.012" />
        <parent link="kamerahalterung" />
        <child link="flanschplatte" />
    </joint>
    <!-- Verbindung zwischen Flanschplatte und Greifer 3.14159265359-->
    <joint name="fixed_link_to_flange" type="fixed">
        <origin rpy="0 0 0" xyz="0 0 0.004" />
        <parent link="flanschplatte" />
        <child link="gripper_base" />
    </joint>
    <material name="aluminum">
        <color rgba="0.5 0.5 0.5 1" />
    </material>
    <material name="plastic">
        <color rgba="0.1 0.1 0.1 1" />
    </material>
    <link name="d435_base_link" />
    <!-- camera body, with origin at bottom screw mount -->
    <joint name="camera_joint" type="fixed">
        <origin rpy="0 0 0" xyz="0 0 0" />
        <parent link="d435_base_link" />
        <child link="camera_bottom_screw_frame" />
    </joint>
    <link name="camera_bottom_screw_frame" />
    <joint name="camera_link_joint" type="fixed">
        <origin rpy="0 0 0" xyz="0.010600000000000002 0.0175 0.0125" />
        <parent link="camera_bottom_screw_frame" />
        <child link="camera_link" />
    </joint>
    <link name="camera_link">
        <visual>
            <!-- the mesh origin is at front plate in between the two infrared camera axes -->
            <origin rpy="1.5707963267948966 0 1.5707963267948966" xyz="0.0043 -0.0175 0" />
            <geometry>
                <mesh filename="package://realsense2_description/meshes/d435.dae" />
            </geometry>
        </visual>
        <collision>
            <origin rpy="0 0 0" xyz="0 -0.0175 0" />
            <geometry>
                <box size="0.02505 0.09 0.025" />
            </geometry>
        </collision>
        <inertial>
            <!-- The following are not reliable values, and should not be used for modeling -->
            <mass value="0.072" />
            <origin xyz="0 0 0" rpy="0 0 0" />
            <inertia ixx="0.003881243" ixy="0.0" ixz="0.0" iyy="0.000498940" iyz="0.0" izz="0.003879257" />
        </inertial>
    </link>
    <!-- camera depth joints and links -->
    <joint name="camera_depth_joint" type="fixed">
        <origin rpy="0 0 0" xyz="0 0 0" />
        <parent link="camera_link" />
        <child link="camera_depth_frame" />
    </joint>
    <link name="camera_depth_frame" />
    <joint name="camera_depth_optical_joint" type="fixed">
        <origin rpy="-1.5707963267948966 0 -1.5707963267948966" xyz="0 0 0" />
        <parent link="camera_depth_frame" />
        <child link="camera_depth_optical_frame" />
    </joint>
    <link name="camera_depth_optical_frame" />
    <!-- camera left IR joints and links -->
    <joint name="camera_infra1_joint" type="fixed">
        <origin rpy="0 0 0" xyz="0 0.0 0" />
        <parent link="camera_link" />
        <child link="camera_infra1_frame" />
    </joint>
    <link name="camera_infra1_frame" />
    <joint name="camera_infra1_optical_joint" type="fixed">
        <origin rpy="-1.5707963267948966 0 -1.5707963267948966" xyz="0 0 0" />
        <parent link="camera_infra1_frame" />
        <child link="camera_infra1_optical_frame" />
    </joint>
    <link name="camera_infra1_optical_frame" />
    <!-- camera right IR joints and links -->
    <joint name="camera_infra2_joint" type="fixed">
        <origin rpy="0 0 0" xyz="0 -0.05 0" />
        <parent link="camera_link" />
        <child link="camera_infra2_frame" />
    </joint>
    <link name="camera_infra2_frame" />
    <joint name="camera_infra2_optical_joint" type="fixed">
        <origin rpy="-1.5707963267948966 0 -1.5707963267948966" xyz="0 0 0" />
        <parent link="camera_infra2_frame" />
        <child link="camera_infra2_optical_frame" />
    </joint>
    <link name="camera_infra2_optical_frame" />
    <!-- camera color joints and links -->
    <joint name="camera_color_joint" type="fixed">
        <origin rpy="0 0 0" xyz="0 0.015 0" />
        <parent link="camera_link" />
        <child link="camera_color_frame" />
    </joint>
    <link name="camera_color_frame" />
    <joint name="camera_color_optical_joint" type="fixed">
        <origin rpy="-1.5707963267948966 0 -1.5707963267948966" xyz="0 0 0" />
        <parent link="camera_color_frame" />
        <child link="camera_color_optical_frame" />
    </joint>
    <link name="camera_color_optical_frame" />
    <joint name="camera_usb_plug_joint" type="fixed">
        <origin rpy="0 0 0" xyz="-0.00605 -0.0528 0" />
        <parent link="camera_link" />
        <child link="camera_usb_plug_link" />
    </joint>
    <link name="camera_usb_plug_link">
        <visual>
            <!-- 0.044850 0.008000 0.018500 -->
            <origin rpy="0 0 1.5707963267948966" xyz="0. -0.022425 0." />
            <geometry>
                <!--box size="0.044850 0.008 0.0185" /-->
                <mesh filename="package://realsense2_description/meshes/plug.stl" />
            </geometry>
            <material name="plastic" />
        </visual>
        <collision>
            <origin rpy="0 0 1.5707963267948966" xyz="0. -0.022425 0." />
            <geometry>
                <!--box size="0.044850 0.008 0.0185" /-->
                <mesh filename="package://realsense2_description/meshes/plug_collision.stl" />
            </geometry>
        </collision>
        <inertial>
            <mass value="0.1" />
            <origin xyz="0 0 0" rpy="0 0 0" />
            <inertia ixx="0.03" iyy="0.03" izz="0.03" ixy="0.0" ixz="0.0" iyz="0.0" />
        </inertial>
    </link>
    <!-- === Joints === -->
    <!-- Fixed Joint for MiR100 to Butler Structure -->
    <joint name="FixedJointMIRtoStructure" type="fixed">
        <parent link="mir_surface" />
        <child link="butler_structure" />
        <origin rpy="0.0 0.0 0.0" xyz="0.383 -0.271 0.0" />
    </joint>
    <!-- Fixed Joint for Butler Structure to UR5 -->
    <joint name="FixedJointStructuretoUR5" type="fixed">
        <origin rpy="0.0 0.0 0.0" xyz="-0.263 0.271 0.540" />
        <parent link="butler_structure" />
        <child link="base_link" />
        <!-- Ensure this is the correct name for the UR5 base link -->
    </joint>
    <!-- Fixed Joint for ur5 tool0 to fixture for d435-->
    <joint name="FixedLinkFixture" type="fixed">
        <origin rpy="0 0 1.57079632679" xyz="0 0 0" />
        <parent link="tool0" />
        <child link="kamerahalterung" />
    </joint>
    <!-- Fixed Joint for fixture to d435 camera -->
    <joint name="FixedLinkCamera" type="fixed">
        <origin rpy="0 -1.57079632679 0" xyz="0.0125 0 0.01" />
        <parent link="Kamera_Basis_KS" />
        <child link="d435_base_link" />
    </joint>
    <transmission name="trans_mir_fl_caster_rotation_joint">
        <type>transmission_interface/SimpleTransmission</type>
        <joint name="mir_fl_caster_rotation_joint">
            <hardwareInterface>hardware_interface/EffortJointInterface</hardwareInterface>
        </joint>
        <actuator name="mir_fl_caster_rotation_joint_motor">
            <hardwareInterface>hardware_interface/EffortJointInterface</hardwareInterface>
            <mechanicalReduction>1</mechanicalReduction>
        </actuator>
    </transmission>
    <transmission name="trans_mir_fl_caster_wheel_joint">
        <type>transmission_interface/SimpleTransmission</type>
        <joint name="mir_fl_caster_wheel_joint">
            <hardwareInterface>hardware_interface/EffortJointInterface</hardwareInterface>
        </joint>
        <actuator name="mir_fl_caster_wheel_joint_motor">
            <hardwareInterface>hardware_interface/EffortJointInterface</hardwareInterface>
            <mechanicalReduction>1</mechanicalReduction>
        </actuator>
    </transmission>
    <transmission name="trans_mir_fr_caster_rotation_joint">
        <type>transmission_interface/SimpleTransmission</type>
        <joint name="mir_fr_caster_rotation_joint">
            <hardwareInterface>hardware_interface/EffortJointInterface</hardwareInterface>
        </joint>
        <actuator name="mir_fr_caster_rotation_joint_motor">
            <hardwareInterface>hardware_interface/EffortJointInterface</hardwareInterface>
            <mechanicalReduction>1</mechanicalReduction>
        </actuator>
    </transmission>
    <transmission name="trans_mir_fr_caster_wheel_joint">
        <type>transmission_interface/SimpleTransmission</type>
        <joint name="mir_fr_caster_wheel_joint">
            <hardwareInterface>hardware_interface/EffortJointInterface</hardwareInterface>
        </joint>
        <actuator name="mir_fr_caster_wheel_joint_motor">
            <hardwareInterface>hardware_interface/EffortJointInterface</hardwareInterface>
            <mechanicalReduction>1</mechanicalReduction>
        </actuator>
    </transmission>
    <transmission name="trans_mir_bl_caster_rotation_joint">
        <type>transmission_interface/SimpleTransmission</type>
        <joint name="mir_bl_caster_rotation_joint">
            <hardwareInterface>hardware_interface/EffortJointInterface</hardwareInterface>
        </joint>
        <actuator name="mir_bl_caster_rotation_joint_motor">
            <hardwareInterface>hardware_interface/EffortJointInterface</hardwareInterface>
            <mechanicalReduction>1</mechanicalReduction>
        </actuator>
    </transmission>
    <transmission name="trans_mir_bl_caster_wheel_joint">
        <type>transmission_interface/SimpleTransmission</type>
        <joint name="mir_bl_caster_wheel_joint">
            <hardwareInterface>hardware_interface/EffortJointInterface</hardwareInterface>
        </joint>
        <actuator name="mir_bl_caster_wheel_joint_motor">
            <hardwareInterface>hardware_interface/EffortJointInterface</hardwareInterface>
            <mechanicalReduction>1</mechanicalReduction>
        </actuator>
    </transmission>
    <transmission name="trans_mir_br_caster_rotation_joint">
        <type>transmission_interface/SimpleTransmission</type>
        <joint name="mir_br_caster_rotation_joint">
            <hardwareInterface>hardware_interface/EffortJointInterface</hardwareInterface>
        </joint>
        <actuator name="mir_br_caster_rotation_joint_motor">
            <hardwareInterface>hardware_interface/EffortJointInterface</hardwareInterface>
            <mechanicalReduction>1</mechanicalReduction>
        </actuator>
    </transmission>
    <transmission name="trans_mir_br_caster_wheel_joint">
        <type>transmission_interface/SimpleTransmission</type>
        <joint name="mir_br_caster_wheel_joint">
            <hardwareInterface>hardware_interface/EffortJointInterface</hardwareInterface>
        </joint>
        <actuator name="mir_br_caster_wheel_joint_motor">
            <hardwareInterface>hardware_interface/EffortJointInterface</hardwareInterface>
            <mechanicalReduction>1</mechanicalReduction>
        </actuator>
    </transmission>
    <transmission name="trans_left_inner_knuckle_joint">
        <type>transmission_interface/SimpleTransmission</type>
        <joint name="left_inner_knuckle_joint">
            <hardwareInterface>hardware_interface/EffortJointInterface</hardwareInterface>
        </joint>
        <actuator name="left_inner_knuckle_joint_motor">
            <hardwareInterface>hardware_interface/EffortJointInterface</hardwareInterface>
            <mechanicalReduction>1</mechanicalReduction>
        </actuator>
    </transmission>
    <transmission name="trans_left_inner_finger_joint">
        <type>transmission_interface/SimpleTransmission</type>
        <joint name="left_inner_finger_joint">
            <hardwareInterface>hardware_interface/EffortJointInterface</hardwareInterface>
        </joint>
        <actuator name="left_inner_finger_joint_motor">
            <hardwareInterface>hardware_interface/EffortJointInterface</hardwareInterface>
            <mechanicalReduction>1</mechanicalReduction>
        </actuator>
    </transmission>
    <transmission name="trans_right_outer_knuckle_joint">
        <type>transmission_interface/SimpleTransmission</type>
        <joint name="right_outer_knuckle_joint">
            <hardwareInterface>hardware_interface/EffortJointInterface</hardwareInterface>
        </joint>
        <actuator name="right_outer_knuckle_joint_motor">
            <hardwareInterface>hardware_interface/EffortJointInterface</hardwareInterface>
            <mechanicalReduction>1</mechanicalReduction>
        </actuator>
    </transmission>
    <transmission name="trans_right_inner_knuckle_joint">
        <type>transmission_interface/SimpleTransmission</type>
        <joint name="right_inner_knuckle_joint">
            <hardwareInterface>hardware_interface/EffortJointInterface</hardwareInterface>
        </joint>
        <actuator name="right_inner_knuckle_joint_motor">
            <hardwareInterface>hardware_interface/EffortJointInterface</hardwareInterface>
            <mechanicalReduction>1</mechanicalReduction>
        </actuator>
    </transmission>
    <transmission name="trans_right_inner_finger_joint">
        <type>transmission_interface/SimpleTransmission</type>
        <joint name="right_inner_finger_joint">
            <hardwareInterface>hardware_interface/EffortJointInterface</hardwareInterface>
        </joint>
        <actuator name="right_inner_finger_joint_motor">
            <hardwareInterface>hardware_interface/EffortJointInterface</hardwareInterface>
            <mechanicalReduction>1</mechanicalReduction>
        </actuator>
    </transmission>
</robot>

